model
name = book_red
size = 3 5 4
scale = 0.05
origin = -y
material type = toon, lighting = smooth, deform = 1 1 
  colors = A:#CC425E B:#EA6262 C:#FFF D:#FCEF8D
voxels
BBB DDD BBB BBB BBB 
ACA ACA ACA ACA ACA 
ACA ACA ACA ACA ACA 
A-A A-A A-A A-A A-A 
