model
name = bookshelf
size = 32 32 10
scale = 0.05
origin = -y
material type = toon, lighting = smooth, deform = 1 1 
  colors = A:#A6555F B:#C97373 C:#873555
voxels
2C28A3C30-CA27(30-2A)30-AC30-3C28A4CA4BA12BA8BA3C30ACA30-AB11(30-2B)30-BA30-AB8(30-2B)30-BA30-AB2(30-2B)30-BA30-AC30A3CA10BA9BA5BA4C28A3C30BCA5(30-2A)30-34A6(30-2A)2(30-34A5(30-2A))30-AC30B3C28A4C28A3C30BCA6(30-2A)30B7(2A30-)2(2A30B6(2A30-))AC30B3C28A4CA8BA13BA3BA3C30BCA30-AB4(30-2B)30-34B30-BA30-AB4(30-2B)30-34B2(30-2B)30-BA30-AB30-2B30-34B4(30-2B)30-BA30-AC30B3CA3BA10BA11BA2(4C28A3C30BCA6(30-2A)30B7(2A30-)2(2A30B6(2A30-))AC30B3C28A)4CA6BA12BA6BA3C30BCA30-AB4(30-2B)30-34B5(30-2B)30-BA30-A33B5(30-2B)30-34B30-BA30-AB2(30-2B)30-BA30-AC30B3CA10BA9BA5BA4C28A3C30BC896AC30B3C28A4C28A3C30AC2A2BA8BA9BA6B67A8BA9BA8BA2B66A10B2(A9B)66A7BA9BA6BA5B66A10B2(A9B)66A8BA9BA8BA2B66A10B2(A9B)66A4BA7BA9BA7B66A10B2(A9B)67A5BA9BA7BA4B2AC30A3C28A2C
