model
name = knight_statue
size = 16 30 16
scale = 0.05
origin = -y
material type = toon, lighting = smooth, deform = 1 1 
  colors = A:#D9BDC8 B:#A6859F
voxels
BBBBBBBBBBBBBBBB ---------------- ---BBBBBBBBBB--- ---BBBBBBBBBB--- ---BBBBBBBBBB--- ---------------- BBBBBBBBBBBBBBBB ---------------- ---------------- ---------------- ---------------- ---------------- ---------------- ---------------- ---------------- ---------------- ---------------- ---------------- ---------------- ---------------- ---------------- ---------------- ---------------- ---------------- ---------------- ---------------- ---------------- ---------------- ---------------- ---------------- 
BBBBBBBBBBBBBBBB -AAAAAAAAAAAAAA- -AAAAAAAAAAAAAA- -AAAAAAAAAAAAAA- -AAAAAAAAAAAAAA- -AAAAAAAAAAAAAA- BBBBBBBBBBBBBBBB ---------------- ---------------- ---------------- ---------------- ---------------- ---------------- ---------------- ---------------- ---------------- ---------------- ---------------- ---------------- ---------------- ---------------- ---------------- ---------------- ---------------- ---------------- ---------------- ---------------- ---------------- ---------------- ---------------- 
BBBBBBBBBBBBBBBB -AAAAAAAAAAAAAA- -AAAAAAAAAAAAAA- -AAAAAAAAAAAAAA- -AAAAAAAAAAAAAA- -AAAAAAAAAAAAAA- BBBBBBBBBBBBBBBB --BBBBBBBBBBBB-- ---------------- ---------------- --BBBBBBBBBBBB-- ---------------- ---------------- ---------------- ---------------- ---------------- ---------------- ---------------- ---------------- ---------------- ---------------- ---------------- ---------------- ---------------- ---------------- ---------------- ---------------- ---------------- ---------------- ---------------- 
BBBBBBBBBBBBBBBB -AAAAAAAAAAAAAA- -AAAAAAAAAAAAAA- -AAAAAAAAAAAAAA- -AAAAAAAAAAAAAA- -AAAAAAAAAAAAAA- BBBBBBBBBBBBBBBB --BAAAAAAAAAAB-- ---AAAAAAAAAA--- ---AAAAAAAAAA--- --BBBBBBBBBBBB-- ---------------- ---------------- ---------------- ---------------- ---------------- ---------------- ---------------- ---------------- ---------------- ---------------- ---------------- ---------------- ---------------- ---------------- ---------------- ---------------- ---------------- ---------------- ---------------- 
BBBBBBBBBBBBBBBB -AAAAAAAAAAAAAA- -AAAAAAAAAAAAAA- -AAAAAAAAAAAAAA- -AAAAAAAAAAAAAA- -AAAAAAAAAAAAAA- BBBBBBBBBBBBBBBB --BAAAAAAAAAAB-- ---AAAAAAAAAA--- ---AAAAAAAAAA--- --BBBBBBBBBBBB-- --B------------- --B------------- --B------------- --B------------- --B------------- -AB------------- -AB------------- --B------------- --B------------- --B------------- --B------------- --B------------- --B------------- --A------------- -AAA------------ -AAA------------ -AAA------------ --A------------- --A------------- 
BBBBBBBBBBBBBBBB -AAAAAAAAAAAAAA- -AAAAAAAAAAAAAA- -AAAAAAAAAAAAAA- -AAAAAAAAAAAAAA- -AAAAAAAAAAAAAA- BBBBBBBBBBBBBBBB --BAAAAAAAAAAB-- ---AAAAAAAAAA--- ---AAAAAAAAAA--- --BBBBBBBBBBBB-- ---------------- ---------------- ---------------- ---------------- ---------------- -BA------------- -BA------------- ---------------- ---------------- ---------------- ---------------- ---------------- ---------------- ---------------- ---------------- ---------------- ---------------- ---------------- ---------------- 
BBBBBBBBBBBBBBBB -AAAAAAAAAAAAAA- -AAAAAAAAAAAAAA- -AAAAAAAAAAAAAA- -AAAAAAAAAAAAAA- -AAAAAAAAAAAAAA- BBBBBBBBBBBBBBBB --BAAAAAAAAAAB-- ---AAAAAAAAAA--- ---AAAAAAAAAA--- --BBBBBBBBBBBB-- ----AAA--AAA---- ---------------- ---------------- ---------------- ---------------- AA-------------- AA-------------- ---------------- ----B------B---- ---BB------BB--- ---BB------BB--- ---------------- ---------------- ---------------- ---------------- ---------------- ---------------- ---------------- ---------------- 
BBBBBBBBBBBBBBBB -AAAAAAAAAAAAAA- -AAAAAAAAAAAAAA- -AAAAAAAAAAAAAA- -AAAAAAAAAAAAAA- -AAAAAAAAAAAAAA- BBBBBBBBBBBBBBBB --BAAAAAAAAAAB-- ---AAAAAAAAAA--- ---AAAAAAAAAA--- --BBBBBBBBBBBB-- ----AAA--AAA---- ----BBB--BBB---- ---------------- ----BBBBBBBB---- ----AAAAAAAA---- AA-------------- AA--BBBAABBB---- ----BAABBAAB---- ----AAABBAAA---- ---BAAABBAAAB--- --BBB------BBB-- -----AA--AA----- -----AA--AA----- -----A----A----- -----AAAAAA----- -----AAAAAA----- ---------------- ---------------- ---------------- 
BBBBBBBBBBBBBBBB -AAAAAAAAAAAAAA- -AAAAAAAAAAAAAA- -AAAAAAAAAAAAAA- -AAAAAAAAAAAAAA- -AAAAAAAAAAAAAA- BBBBBBBBBBBBBBBB --BAAAAAAAAAAB-- ---AAAAAAAAAA--- ---AAAAAAAAAA--- --BBBBBBBBBBBB-- ----AAA--AAA---- ----AAA--AAA---- ----AAAAAAAA---- ----BAAAAAAB-A-- ----AAAAAAAAABA- AA---BBBBBB--AA- AAA-AAAAAAAA-AA- -AAAAAAAAAAAAAA- --AAAAAAAAAAAA-- ---BABBBBBBAB--- --BBB-BBBB-BBB-- -----AABBAA----- -----AABBAA----- -----ABBBBA----- -----AAAAAA----- -----AAAAAA----- ---------------- ---------------- ---------------- 
BBBBBBBBBBBBBBBB -AAAAAAAAAAAAAA- -AAAAAAAAAAAAAA- -AAAAAAAAAAAAAA- -AAAAAAAAAAAAAA- -AAAAAAAAAAAAAA- BBBBBBBBBBBBBBBB --BAAAAAAAAAAB-- ---AAAAAAAAAA--- ---AAAAAAAAAA--- --BBBBBBBBBBBB-- ----BAB--BAB---- ----AAA--AAA---- ----AAAAAAAA---- ----BAAAAAAB-A-- ----AAAAAAAAABA- -----BBBBBB--AA- -BA-AAAAAAAA-AB- -AAAAAAAAAAAAAA- --AAAAAAAAAAAA-- ---BABBBBBBAB--- --BBB-BBBB-BBB-- -----AAAAAA----- -----AAAAAA----- -----AAAAAA----- -----AAAAAA----- -----AAAAAA----- ---------------- ---------------- ---------------- 
BBBBBBBBBBBBBBBB -AAAAAAAAAAAAAA- -AAAAAAAAAAAAAA- -AAAAAAAAAAAAAA- -AAAAAAAAAAAAAA- -AAAAAAAAAAAAAA- BBBBBBBBBBBBBBBB --BAAAAAAAAAAB-- ---AAAAAAAAAA--- ---AAAAAAAAAA--- --BBBBBBBBBBBB-- ----AAA--AAA---- ----AAA--AAA---- ----AABBBBAA---- ----BBBAABBB---- ----AAAAAAAA---- ---------------- ----AAAAAAAA---- ----AAAAAAAA---- ----AAAAAAAA---- ---BABBBBBBAB--- --BBB------BBB-- -----AAAAAA----- -----AAAAAA----- -----AAAAAA----- -----AAAAAA----- -----AAAAAA----- ---------------- ---------------- ---------------- 
BBBBBBBBBBBBBBBB -AAAAAAAAAAAAAA- -AAAAAAAAAAAAAA- -AAAAAAAAAAAAAA- -AAAAAAAAAAAAAA- -AAAAAAAAAAAAAA- BBBBBBBBBBBBBBBB --BAAAAAAAAAAB-- ---AAAAAAAAAA--- ---AAAAAAAAAA--- --BBBBBBBBBBBB-- ---------------- ---------------- ---------------- ---------------- ---------------- ---------------- ---------------- ---------------- ----B------B---- ---BB------BB--- ---BB------BB--- ---------------- ---------------- ---------------- ---------------- ---------------- ---------------- ---------------- ---------------- 
BBBBBBBBBBBBBBBB -AAAAAAAAAAAAAA- -AAAAAAAAAAAAAA- -AAAAAAAAAAAAAA- -AAAAAAAAAAAAAA- -AAAAAAAAAAAAAA- BBBBBBBBBBBBBBBB --BAAAAAAAAABB-- ---AAAAAAAAAA--- ---AAAAAAAAAA--- --BBBBBBBBBBBB-- ---------------- ---------------- ---------------- ---------------- ---------------- ---------------- ---------------- ---------------- ---------------- ---------------- ---------------- ---------------- ---------------- ---------------- ---------------- ---------------- ---------------- ---------------- ---------------- 
BBBBBBBBBBBBBBBB -AAAAAAAAAAAAAA- -AAAAAAAAAAAAAA- -AAAAAAAAAAAAAA- -AAAAAAAAAAAAAA- -AAAAAAAAAAAAAA- BBBBBBBBBBBBBBBB --BBBBBBBBBBBB-- ---------------- ---------------- --BBBBBBBBBBBB-- ---------------- ---------------- ---------------- ---------------- ---------------- ---------------- ---------------- ---------------- ---------------- ---------------- ---------------- ---------------- ---------------- ---------------- ---------------- ---------------- ---------------- ---------------- ---------------- 
BBBBBBBBBBBBBBBB -AAAAAAAAAAAAAA- -AAAAAAAAAAAAAA- -AAAAAAAAAAAAAA- -AAAAAAAAAAAAAA- -AAAAAAAAAAAAAA- BBBBBBBBBBBBBBBB ---------------- ---------------- ---------------- ---------------- ---------------- ---------------- ---------------- ---------------- ---------------- ---------------- ---------------- ---------------- ---------------- ---------------- ---------------- ---------------- ---------------- ---------------- ---------------- ---------------- ---------------- ---------------- ---------------- 
BBBBBBBBBBBBBBBB ---------------- ---------------- ---------------- ---------------- ---------------- BBBBBBBBBBBBBBBB ---------------- ---------------- ---------------- ---------------- ---------------- ---------------- ---------------- ---------------- ---------------- ---------------- ---------------- ---------------- ---------------- ---------------- ---------------- ---------------- ---------------- ---------------- ---------------- ---------------- ---------------- ---------------- ---------------- 
