model
name = monu3
size = 97 79 97
scale = 0.05
origin = -y
material type = toon, lighting = smooth, deform = 1 1 
  colors = A:#C7C29A B:#B2C553 C:#A7A279 D:#F8A833 E:#677158 F:#FFF G:#596636 H:#0FA9BD I:#7F8257
voxels
3(97B7566-)97B133-F7432-97B36-F50-3E42-3F49-3(3E94-)3E7088-97B87-3E43-F50-3(3E94-)3E7088-97B87-3E83-F10-3(3E94-)3E7088-97B40-3E33-F47-F12-3E6-F25-3F59-3E7329-97B27-F12-3E6-F73-3F11-3E5-3F25-F60-3E7329-97B15-3E22-3E69-3E9-F12-3E6-F62-3E22-3E7329-97B15-2(3E94-)3E7354-97B15-2(3E11-3E39-3E11-3E24-)3E11-3E39-3E11-3E38-3E39-3E11-3E80-3E11-3E94-3E6993-97B29-3(3E39-3E11-3E38-)3E39-3E11-3E80-3E11-3E94-3E6993-97B29-3E39-3E11-3E38-3E26-F12-2(3E11-3E38-3E39-)3E11-3E80-3E11-3E94-3E6993-97B58-F9-2E73-F10-3F8-2E7399-97B46-F21-2E72-3F10-F9-2E7399-97B112-F30-F7422-97B15-F54-3E38-3F53-5(3E94-)3E6911-97B70-3E39-F54-5(3E94-)3E6911-97B70-6(3E94-)3E6911-97B62-3E5-3E49-F36-4(3E5-3E86-)3E5-3E94-3E6911-97B25-F36-3E56-3F35-4(3E94-)3E7016-97B62-3E57-F36-3E23-F70-3(3E94-)3E7016-97B88-F95-3F7379-97B185-F7380-4(97B7566-)97B89-3E90-F3-3E94-3E7280-97B6-7A55-7A10-F3-3E11-7A55-7A9-3F2-3E11-7A55-7A14-3E11-2(7A55-7A28-)7A55-15(7A90-)7A5551-97B6-7A55-7A14-3E11-7A55-7A10-F3-3E11-7A55-7A14-3E11-2(7A55-7A28-)7A55-7A29-5G56-14(7A90-)7A91-5G3(5455-97B6-5(7A55-7A28-)7A55-7A29-G3DG56-14(7A90-)7A91-G3DG)5455-97B6-5(7A55-7A28-)7A55-7A29-5G56-14(7A90-)7A91-5G5455-3(97B6-5(7A55-7A28-)7A55-15(7A90-)7A5551-)2(97B6-5(7A55-7A28-)7A55-15(7A90-)7A2301-G3249-)2(97B6-7A28-5(15A12-2(7A28-))7(15A12-7A63-)15A12-8(7A90-)7A2301-H3249-)97B6-7A28-5(2A11-2A12-2(7A28-))7(2A11-2A12-7A63-)2A11-2A12-8(7A90-)7A2301-H3249-97B6-7A28-5(2A11-2A12-2(7A28-))7(2A11-2A12-7A63-)2A11-2A12-8(7A90-)7A2301-H2458-9D185-3(9D88-)9D297-97B6-7(16A19-2A2-7C2-2A12-22A13-)3(2A3-11A19-2A2-7C2-2A12-22A13-16A19-2A2-7C2-2A12-22A13-)2A3-11A23-7C3(16-22A13-16A6-24C16-22A13-2A3-11A6-24C)16-22A13-22A24C16-22A13(52-A5-A31-A5-A)2(52-2A3-2A31-A5-A)5(52-7A31-A5-A)52-7A31-2(2A3-2A90-)7A55-H34-12(7A90-)7A77-20A11(90-A5-A)89-9D89-7D89-3(9D88-)9D89-2(7D90-)7D7-97B6-13(16A19-2A2-7C2-2A12-22A13-)16A23-7C6(16-22A13-16A6-24C)16-22A13-22A24C16-22A1313-2(A5-A90-)5(7A90-)7A31-2(A5-A53-5A32-)3(7A53-5A32-)10(7A90-)7A77-20A1156-9D89-7D89-3(9D88-)9D89-2(7D90-)7D7-97B6-13(16A19-2A2-7C2-2A12-22A13-)16A23-7C6(16-22A13-16A6-24C)16-22A13-22A24C16-22A1507-5(7A90-)7A91-5A92-3(5A32-7A53-)A3-A32-10(7A90-)7A77-20A1156-9D89-7D89-3(9D88-)9D89-2(7D90-)2D3-2D7-97B6-13(16A19-2A2-7C2-2A12-22A13-)16A23-7C6(16-22A13-16A6-24C)16-22A13-22A24C16-22A1507-5(7A90-)7A91-5A92-5A32-7A46-2G5H5A5H2G25-7A53-5A32-7A53-A3-A32-10(7A90-)7A77-20A1156-9D89-7D89-3(9D88-)9D89-2(7D90-)2D3-2D7-97B6-13(16A19-2A2-7C2-2A12-22A13-)16A23-7C6(16-22A13-16A6-24C)16-22A13-22A24C16-22A1507-5(7A90-)7A91-5A92-3(5A32-7A53-)A3-A32-10(7A90-)7A77-20A1156-9D89-7D89-3(9D88-)9D89-2(7D90-)2D3-2D7-97B6-13(16A19-2A2-7C2-2A12-22A13-)16A23-7C6(16-22A13-16A6-24C)16-22A13-22A24C16-22A1313-2(A4-2A90-)5(7A90-)7A31-2(A5-A53-5A32-)3(7A53-5A32-)10(7A90-)7A77-20A1156-9D89-7D89-3(9D88-)9D89-2(7D90-)7D7-97B6-13(16A19-2A2-7C2-2A12-22A13-)16A23-7C6(16-22A13-16A6-24C)16-22A13-22A24C16-22A13(52-A5-A31-A5-A)2(52-2A3-2A31-A5-A)5(52-7A31-A5-A)52-7A31-2(2A3-2A90-)7A55-H34-12(7A90-)7A77-20A11(90-A5-A)89-9D89-7D89-3(9D88-)9D89-2(7D90-)7D7-97B41-12(2A11-2A27-7A48-)2A11-2A27-7A90-7(7A52-7C31-)7A2286-H1295-7A1156-9D185-3(9D88-)9D297-97B41-12(2A11-2A27-7A48-)2A11-2A2(27-7A90-7(7A52-7C31-)7A2286-H1295-7A1947-97B41-12(15A27-7A48-)15A)27-7A90-7(7A52-7C31-)7A2286-H2(1295-7A1947-97B83-13(7A90-)7(7A52-7C31-)7A2286-G)1295-5(7A1947-97B83-13(7A90-)7(7A52-7C31-)7A3582-)7A1947-97B83-7A68-F21-12(7A90-)7(7A52-7C31-)7A3582-7A1947-97B61-F21-7A67-3F20-12(7A90-)7(7A52-7C31-)7A3582-7A1947-97B83-7A68-F21-12(7A90-)7(7A52-7C31-)7A3582-3(7A1947-97B1403-6(7C90-)7C3620-)7A1947-97B1985-7A3620-2(7A1947-97B1985-7A3582-7A31-)7A1947-97B113-F1871-7A3582-7A31-7A1947-97B16-F95-3F1870-7A3582-7A31-7A1947-97B113-F1871-7A3582-7A31-7A1947-97B45-7A71-F18-19(7A90-)7A3582-7A31-7A1947-97B26-F7-2E3-3E3-7A70-3F6-2E3-3E3-7A79-2E3-2(3E3-7A84-)3E3-16(7A90-)7A3582-7A31-7A1947-97B14-4E16-2E3-3E3-7A59-4E8-F7-2E3-3E3-7A59-4E16-2E3-3E3-7A59-4E21-3E3-7A84-3E3-16(7A90-)7A3582-7A31-7A1947-97B14-4E21-3E3-7A59-4E21-3E3-7A31-F27-4E21-3E3-7A59-4E21-3E3-7A84-3E3-16(7A90-)7A3582-7A31-7A1947-97B14-4E10-4E13-7A31-F27-4E10-4E13-7A30-3F26-4E10-4E13-7A59-4E10-3(4E13-7A73-)4E13-14(7A90-)7A3582-7A31-7A1947-97B14-4E10-4E13-7A59-4E10-4E13-7A31-F27-4E10-4E13-7A59-4E10-3(4E13-7A73-)4E13-14(7A90-)7A3582-7A31-7A1947-97B28-6(4E13-7A73-)4E13-14(7A90-)7A3582-7A29-11A1945-97B28-6(4E13-7A73-)4E13-14(7A90-)7A3582-7A29-11A91-A1024-9D29-9D147-3(9D29-9D50-)9D29-9D297-97B45-37(7A90-)5(3A-3A90-)15(7A90-)47A50-A5-A31-7A10(52-A5-A37-A)51-9D29-9D51-7D89-3(9D29-9D50-)9D29-9D51-2(7D31-7D52-)7D31-7D7-97B6-3(3E36-7A51-)3E36-54(7A90-)47A88-A5IA1021-9D29-9D51-7D32-5D52-3(9D29-9D50-)9D29-9D51-2(7D31-7D52-)7D31-7D7-97B6-3(3E36-7A51-)3E36-54(7A90-)47A88-AI3DIA1021-9D29-9D51-7D32-5D52-3(9D29-9D50-)9D29-9D51-2(7D31-7D52-)2D3-2D31-2D3-2D7-97B6-3(3E9-3E24-7A51-)3E36-33(7A90-)7A91-4(5A92-)5A91-15(7A90-)47A87-2A2(ID)I2A1020-9D29-9D51-7D32-5D52-3(9D29-9D50-)9D29-9D51-2(7D31-7D52-)2D3-2D31-2D3-2D7-97B18-2(3E24-7A63-)3E24-55(7A90-)47A88-AI3DIA1021-9D29-9D51-7D32-5D52-3(9D29-9D50-)9D29-9D51-2(7D31-7D52-)2D3-2D31-2D3-2D7-97B18-3E24-7A63-3E19-F4-7A10-F52-3E24-55(7A90-)47A88-A5IA1021-9D29-9D51-7D32-5D52-3(9D29-9D50-)9D29-9D51-2(7D31-7D52-)7D31-7D7-97B40-F4-7A10-F73-3F3-7A9-3F78-35(7A90-)5(3A-3A90-)15(7A90-)47A50-A5-A31-7A10(52-A5-A31-A5-A)51-9D29-9D51-7D89-3(9D29-9D50-)9D29-9D51-2(7D31-7D52-)7D31-7D7-97B137-F21-F5450-11A91-A1024-9D29-9D147-3(9D29-9D50-)9D29-9D297-97B5610-11A1945-5(97B7566-)
