model
name = sword
size = 7 16 3
scale = 0.05
origin = -y
material type = toon, lighting = smooth, deform = 1 1 
  colors = A:#D9BDC8 B:#A6555F C:#A6859F D:#C97373
voxels
---B--- ------- ------- ------- ---B--- ---B--- ------- ------- ------- ------- ------- ------- ------- ------- ------- ------- 
--BDB-- ---D--- ---B--- ---D--- -DDBDD- BBADABB --ACA-- --ACA-- --ACA-- --ACA-- --ACA-- --ACA-- --ACA-- --ACA-- --ACA-- ---A--- 
---B--- ------- ------- ------- ---B--- ---B--- ------- ------- ------- ------- ------- ------- ------- ------- ------- ------- 
