model
name = table_fancy_2x3
revision = 67
size = 69 17 32
scale = 0.05
origin = -y
shell = Outline 0.25
material type = toon, lighting = smooth, deform = 1 1
  colors = C:#A32858 D:#FFB879
material type = basic, lighting = smooth, roughness = 0, refractionRatio = 1, side = back
  colors = Outline:#000
voxels
9318-64D1109-15(DC)D2C15(DC)D1109-64C1109-CD29C2D29CDC1109-2CD18C7D3C2D3C7D18CD2C1109-8CDCD2C5D3CD20CD3C5D2CDCD8C1109-5D5CD5C3D2C2D7C4D7C2D2C3D5CD5C5D1109-10C5D3CD8CDC2D2C2DCD8CD3C5D10C2(1109-6D12C4D20C4D12C6D)1109-10C5D3CD8CDC2D2C2DCD8CD3C5D10C1109-5D5CD5C3D2C2D7C4D7C2D2C3D5CD5C5D1109-8CDCD2C5D3CD20CD3C5D2CDCD8C1109-2CD18C7D3C2D3C7D18CD2C1109-CD29C2D29CDC1109-64C1109-15(DC)D2C15(DC)D1109-64D8213-
